2025-02-24 09:28:17,049 INFO    MainThread:25970 [wandb_setup.py:_flush():67] Current SDK version is 0.19.7
2025-02-24 09:28:17,049 INFO    MainThread:25970 [wandb_setup.py:_flush():67] Configure stats pid to 25970
2025-02-24 09:28:17,049 INFO    MainThread:25970 [wandb_setup.py:_flush():67] Loading settings from /Users/lumignatti/.config/wandb/settings
2025-02-24 09:28:17,050 INFO    MainThread:25970 [wandb_setup.py:_flush():67] Loading settings from /Users/lumignatti/Documents/RLbot/wandb/settings
2025-02-24 09:28:17,050 INFO    MainThread:25970 [wandb_setup.py:_flush():67] Loading settings from environment variables
2025-02-24 09:28:17,050 INFO    MainThread:25970 [wandb_init.py:setup_run_log_directory():647] Logging user logs to /Users/lumignatti/Documents/RLbot/wandb/run-20250224_092817-6mfudt4u/logs/debug.log
2025-02-24 09:28:17,050 INFO    MainThread:25970 [wandb_init.py:setup_run_log_directory():648] Logging internal logs to /Users/lumignatti/Documents/RLbot/wandb/run-20250224_092817-6mfudt4u/logs/debug-internal.log
2025-02-24 09:28:17,050 INFO    MainThread:25970 [wandb_init.py:init():761] calling init triggers
2025-02-24 09:28:17,050 INFO    MainThread:25970 [wandb_init.py:init():766] wandb.init called with sweep_config: {}
config: {'n_proc': 8, 'min_inference_size': 7, 'timestep_limit': 1000000000, 'exp_buffer_size': 150000, 'ts_per_iteration': 50000, 'standardize_returns': True, 'standardize_obs': False, 'policy_layer_sizes': [512, 512], 'critic_layer_sizes': [512, 512], 'ppo_epochs': 1, 'ppo_batch_size': 50000, 'ppo_minibatch_size': 50000, 'ppo_ent_coef': 0.01, 'ppo_clip_range': 0.2, 'gae_lambda': 0.95, 'gae_gamma': 0.99, 'policy_lr': 5e-05, 'critic_lr': 5e-05, 'shm_buffer_size': 8192, '_wandb': {}}
2025-02-24 09:28:17,050 INFO    MainThread:25970 [wandb_init.py:init():784] starting backend
2025-02-24 09:28:17,050 INFO    MainThread:25970 [wandb_init.py:init():788] sending inform_init request
2025-02-24 09:28:17,094 INFO    MainThread:25970 [backend.py:_multiprocessing_setup():97] multiprocessing start_methods=spawn,fork,forkserver, using: spawn
2025-02-24 09:28:17,095 INFO    MainThread:25970 [wandb_init.py:init():803] backend started and connected
2025-02-24 09:28:17,098 INFO    MainThread:25970 [wandb_init.py:init():896] updated telemetry
2025-02-24 09:28:17,100 INFO    MainThread:25970 [wandb_init.py:init():920] communicating run to backend with 90.0 second timeout
2025-02-24 09:28:17,858 INFO    MainThread:25970 [wandb_init.py:init():995] starting run threads in backend
2025-02-24 09:28:17,977 INFO    MainThread:25970 [wandb_run.py:_console_start():2377] atexit reg
2025-02-24 09:28:17,977 INFO    MainThread:25970 [wandb_run.py:_redirect():2227] redirect: wrap_raw
2025-02-24 09:28:17,977 INFO    MainThread:25970 [wandb_run.py:_redirect():2292] Wrapping output streams.
2025-02-24 09:28:17,977 INFO    MainThread:25970 [wandb_run.py:_redirect():2317] Redirects installed.
2025-02-24 09:28:17,979 INFO    MainThread:25970 [wandb_init.py:init():1037] run started, returning control to user process
2025-02-24 09:29:44,953 INFO    MainThread:25970 [wandb_run.py:_finish():2112] finishing run lucamignatti-personal/rlgym-ppo/6mfudt4u
2025-02-24 09:29:44,954 INFO    MainThread:25970 [wandb_run.py:_atexit_cleanup():2342] got exitcode: 0
2025-02-24 09:29:44,955 INFO    MainThread:25970 [wandb_run.py:_restore():2324] restore
2025-02-24 09:29:44,955 INFO    MainThread:25970 [wandb_run.py:_restore():2330] restore done
2025-02-24 09:29:45,902 WARNING MsgRouterThr:25970 [router.py:message_loop():77] message_loop has been closed
Traceback (most recent call last):
  File "/Users/lumignatti/miniconda3/lib/python3.12/site-packages/wandb/sdk/interface/router_sock.py", line 28, in _read_message
    resp = self._sock_client.read_server_response(timeout=1)
           ^^^^^^^^^^^^^^^^^^^^^^^^^^^^^^^^^^^^^^^^^^^^^^^^^
  File "/Users/lumignatti/miniconda3/lib/python3.12/site-packages/wandb/sdk/lib/sock_client.py", line 285, in read_server_response
    data = self._read_packet_bytes(timeout=timeout)
           ^^^^^^^^^^^^^^^^^^^^^^^^^^^^^^^^^^^^^^^^
  File "/Users/lumignatti/miniconda3/lib/python3.12/site-packages/wandb/sdk/lib/sock_client.py", line 270, in _read_packet_bytes
    raise SockClientClosedError
wandb.sdk.lib.sock_client.SockClientClosedError

The above exception was the direct cause of the following exception:

Traceback (most recent call last):
  File "/Users/lumignatti/miniconda3/lib/python3.12/site-packages/wandb/sdk/interface/router.py", line 70, in message_loop
    msg = self._read_message()
          ^^^^^^^^^^^^^^^^^^^^
  File "/Users/lumignatti/miniconda3/lib/python3.12/site-packages/wandb/sdk/interface/router_sock.py", line 30, in _read_message
    raise MessageRouterClosedError from e
wandb.sdk.interface.router.MessageRouterClosedError
2025-02-24 09:29:45,904 INFO    MsgRouterThr:25970 [mailbox.py:close():115] Closing mailbox, abandoning 2 handles.
